<mujoco>
	<option	gravity="0 0 -9.81" density="1" viscosity="1e-5" integrator="RK4"/>
	<!--<option	timestep="0.01" gravity="0 0 -9.81" density="1" viscosity="1e-5" integrator="RK4"/>-->
	<asset>
		<texture builtin="gradient" type="skybox" height="100" width="100" rgb1="1 1 1" rgb2="0 0 0"/>
		<texture name="texgeom" builtin="flat" height="1278" mark="cross" markrgb="1 1 1" random="0.01" rgb1="0.8 0.6 0.4" rgb2="0.8 0.6 0.4" type="cube" width="127"/>
		<texture name="texplane" builtin="checker" height="100" width="100" rgb1="0 0 0" rgb2="0.8 0.8 0.8" type="2d"/>
		<material name="MatPlane" reflectance="0.5" shininess="1" specular="1" texrepeat="60 60" texture="texplane"/>
		<material name="geom" texture="texgeom" texuniform="true"/>
	</asset>
  <default>
    <default class="car1_wheel">
      <geom euler="90 0 0" fitscale="1.2" type="cylinder" size=".05 0.02" friction="2 0.005 0.0001" contype="1" conaffinity="0" mass="0.498952"/>
    </default>
    <default class="car1_steering">
      <joint type="hinge" axis="0 0 1" limited="true" frictionloss="0.01" damping="0.001" armature="0.0002" range="-0.38 0.38"/>
    </default>
    <default class="car1_throttle">
      <joint type="hinge" axis="0 1 0" frictionloss="0.001" damping="0.01" armature="0.01" limited="false"/>
    </default>
  </default>
  <worldbody>
  	<light diffuse=".5 .5 .5" pos="0 0 3" dir="0 0 -1"/>
	<geom conaffinity="1" condim="3" material="MatPlane" name="floor" pos="0 0 0" rgba="1 1 1 1" size="10 10 0.1" type="plane"/>
		
    <body name="car1" pos="0.0 1.0 0.0" euler="0 0 0.0">
      <camera name="car1_third_person" mode="fixed" pos="-1 0 1" xyaxes="0 -1 0 0.707 0 0.707"/>
      <joint type="free"/>

      <camera name="car1_realsense_d435i" mode="fixed" pos="-0.005 0 .165" euler="0 4.712 4.712"/>
      <site name="car1_imu" pos="-0.005 0 .165"/>

      <geom name="car1_realsense_d435i" size="0.012525 0.045 0.0125" pos="0.0123949 0 0.162178" mass="0.072" type="box"/>

      <body name="car1_steering_wheel" pos="0.1385 0 0.0488">
        <joint class="car1_steering" name="car1_steering_wheel"/>
        <geom class="car1_wheel"rgba=".1 .1 .1 1" contype="0" conaffinity="0" mass="0.01"/>
      </body>

      <body name="car1_wheel_fl" pos="0.1385 0.115 0.0488">
        <joint class="car1_steering" name="car1_wheel_fl_steering"/>
        <joint class="car1_throttle" name="car1_wheel_fl_throttle"/>
        <geom class="car1_wheel"/>
        <geom class="car1_wheel" rgba=".1 .1 .1 1" contype="0" conaffinity="0" group="1"/>
      </body>
      <body name="car1_wheel_fr" pos="0.1385 -0.115 0.0488">
        <joint class="car1_steering" name="car1_wheel_fr_steering"/>
        <joint class="car1_throttle" name="car1_wheel_fr_throttle"/>
        <geom class="car1_wheel"/>
        <geom class="car1_wheel" rgba=".1 .1 .1 1" contype="0" conaffinity="0" group="1"/>
      </body>
      <body name="car1_wheel_bl" pos="-0.158 0.115 0.0488">
        <joint class="car1_throttle" name="car1_wheel_bl_throttle"/>
        <geom class="car1_wheel"/>
        <geom class="car1_wheel" rgba=".1 .1 .1 1" contype="0" conaffinity="0" group="1"/>
      </body>
      <body name="car1_wheel_br" pos="-0.158 -0.115 0.0488">
        <joint class="car1_throttle" name="car1_wheel_br_throttle"/>
        <geom class="car1_wheel"/>
        <geom class="car1_wheel" rgba=".1 .1 .1 1" contype="0" conaffinity="0" group="1"/>
      </body>
    </body>
  </worldbody>
  <actuator>
    <position class="car1_steering" kp="25.0" name="car1_steering_pos" joint="car1_steering_wheel"/>
    <velocity kv="100" gear="0.04" forcelimited="true" forcerange="-500 500" name="car1_throttle_velocity" tendon="car1_throttle"/>
  </actuator>
  <equality>
    <!-- taylor expansion of delta_l = arctan(L/(L/tan(delta) - W/2)) with L,W in reference to kinematic car model -->
    <joint joint1="car1_wheel_fl_steering" joint2="car1_steering_wheel" polycoef="0 1 0.375 0.140625 -0.0722656"/>

    <!-- taylor expansion of delta_r = arctan(L/(L/tan(delta) + W/2)) with L,W in reference to kinematic car model -->
    <joint joint1="car1_wheel_fr_steering" joint2="car1_steering_wheel" polycoef="0 1 -0.375 0.140625 0.0722656"/>
  </equality>
  <tendon>
    <fixed name="car1_throttle">
      <joint joint="car1_wheel_fl_throttle" coef="0.25"/>
      <joint joint="car1_wheel_fr_throttle" coef="0.25"/>
      <joint joint="car1_wheel_bl_throttle" coef="0.25"/>
      <joint joint="car1_wheel_br_throttle" coef="0.25"/>
    </fixed>
  </tendon>
  <sensor>
    <accelerometer name="car1_accelerometer" site="car1_imu" />
    <gyro name="car1_gyro" site="car1_imu" />
    <velocimeter name="car1_velocimeter" site="car1_imu" />
  </sensor>
</mujoco>