<mujoco>
	<option	gravity="0 0 -9.81" density="1" viscosity="1e-5" integrator="RK4"/>
	<!--<option	timestep="0.01" gravity="0 0 -9.81" density="1" viscosity="1e-5" integrator="RK4"/>-->
	<asset>
		<texture builtin="gradient" type="skybox" height="100" width="100" rgb1="1 1 1" rgb2="0 0 0"/>
		<texture name="texgeom" builtin="flat" height="1278" mark="cross" markrgb="1 1 1" random="0.01" rgb1="0.8 0.6 0.4" rgb2="0.8 0.6 0.4" type="cube" width="127"/>
		<texture name="texplane" builtin="checker" height="100" width="100" rgb1="0 0 0" rgb2="0.8 0.8 0.8" type="2d"/>
		<material name="MatPlane" reflectance="0.5" shininess="1" specular="1" texrepeat="60 60" texture="texplane"/>
		<material name="geom" texture="texgeom" texuniform="true"/>
	</asset>
  <default>
    <default class="wheel">
      <geom euler="90 0 0" fitscale="1.2" type="cylinder" size=".04 0.01" friction="2 0.005 0.0001" contype="1" conaffinity="0" mass="0.498952"/>
    </default>
    <default class="throttle">
      <joint type="hinge" axis="0 1 0" frictionloss="0.001" damping="0.01" armature="0.01" limited="false"/>
    </default>
  </default>
  <worldbody>
  	<light diffuse=".5 .5 .5" pos="0 0 3" dir="0 0 -1"/>
	<geom conaffinity="1" condim="3" material="MatPlane" name="floor" pos="0 0 0" rgba="1 1 1 1" size="10 10 0.1" type="plane"/>
		
    <body name="twho_wheel" pos="0 0 0.2" euler="0 90 0">
      <camera name="third_person" mode="fixed" pos="-.4 0 -.4" euler="0 215 270"/>
      <joint type="free"/>

      <camera name="realsense_d435i" mode="fixed" pos="-0.05 0 .075" euler="0 215 270"/>
	  <geom type="box" size=".01 .04 .1" rgba=".9 .9 .9 1"/>
      <site name="imu" pos="0 0 0"/>

      <geom name="realsense_d435i" size="0.012525 0.045 0.0125" pos="-0.05 0 .075" mass="0.072" type="box"/>

      <body name="wheel_left" pos="0 0.06 -0.1">
        <joint class="throttle" name="wheel_left_throttle"/>
        <geom class="wheel"/>
        <geom class="wheel" rgba=".1 .1 .1 1" contype="0" conaffinity="0" group="1"/>
      </body>
      <body name="wheel_right" pos="0 -0.06 -0.1">
        <joint class="throttle" name="wheel_right_throttle"/>
        <geom class="wheel"/>
        <geom class="wheel" rgba=".1 .1 .1 1" contype="0" conaffinity="0" group="1"/>
      </body>
	  <body name="caster" pos=".03 0 .08" euler='0 0 0'>
	  	<joint type="ball" frictionloss="0.01" damping="0.01" armature="0.01" limited="false"/>
		<geom type="sphere" size=".01" rgba=".3 .3 .3 1"/>
	  </body>
    </body>
  </worldbody>
  <actuator>
    <velocity kv="100" gear="0.04" forcelimited="true" forcerange="-500 500" name="throttle_velocity_left" tendon="throttle_left"/>
	<velocity kv="100" gear="0.04" forcelimited="true" forcerange="-500 500" name="throttle_velocity_right" tendon="throttle_right"/>
  </actuator>
  <tendon>
    <fixed name="throttle_left">
      <joint joint="wheel_left_throttle" coef="0.25"/>
    </fixed>
	<fixed name="throttle_right">
      <joint joint="wheel_right_throttle" coef="0.25"/>
    </fixed>
  </tendon>
  <sensor>
    <accelerometer name="accelerometer" site="imu" />
    <gyro name="gyro" site="imu" />
    <velocimeter name="velocimeter" site="imu" />
  </sensor>
</mujoco>