<mujoco>
    <option timestep="0.001" integrator="RK4" gravity="0 0 0" density="1" viscosity="1e-5" >
		<flag sensornoise="enable" energy="enable" contact="disable" />
	</option>
    <asset>
        <texture builtin="gradient" type="skybox" height="100" width="100" rgb1="1 1 1" rgb2="0 0 0"/>
        <texture name="texgeom" builtin="flat" height="1278" mark="cross" markrgb="1 1 1" random="0.01" rgb1="0.8 0.6 0.4" rgb2="0.8 0.6 0.4" type="cube" width="127"/>
        <texture name="texplane" builtin="checker" height="100" width="100" rgb1="0 0 0" rgb2="0.8 0.8 0.8" type="2d"/>
        <material name="MatPlane" reflectance="0.5" shininess="1" specular="1" texrepeat="60 60" texture="texplane"/>
        <material name="geom" texture="texgeom" texuniform="true"/>
    </asset>
	<worldbody>
        <light diffuse=".5 .5 .5" pos="0 0 3" dir="0 0 -1"/>
		<geom conaffinity="1" condim="3" material="MatPlane" name="floor" pos="0 0 0" rgba="1 1 1 1" size="3 3 0.1" type="plane"/>
		<body pos=".5 0 1" euler="0 90 0">
			<joint name="pin" type="hinge" axis="-1 0 0"  pos="0 0 -.5"/>
			<geom type="cylinder" size="0.05 0.5" rgba=".8 .2 .2 1"  mass="1"/>
            <body pos="0 0 1" euler="0 0 0">
                <joint name="pin2" type="hinge" axis="-1 0 0"  pos="0 0 -.5"/>
                <geom type="cylinder" size="0.05 0.5" rgba=".2 .8 .2 1" mass="1"/>
                <site name="tip" size="0.1" pos="0 0 0.5"/>
            </body>
		</body>
	</worldbody>
    <actuator>
		<position name="pservo1" joint="pin" kp="1000" />
		<velocity name="vservo1" joint="pin" kv="100" />
		<position name="pservo2" joint="pin2" kp="1000" />
		<velocity name="vservo2" joint="pin2" kv="100" />
	</actuator>
    <sensor>
        <framepos objtype="site" objname="tip" noise="0.1"/>
        <framelinvel objtype="site" objname="tip" noise="0.1" />
    </sensor>
</mujoco>
